<?xml version="1.0" ?>
<!-- =================================================================================== -->
<!-- |    This document was autogenerated by xacro from car.xacro                      | -->
<!-- |    EDITING THIS FILE BY HAND IS NOT RECOMMENDED                                 | -->
<!-- =================================================================================== -->
<robot name="robot">
  <gazebo>
    <!--plugin
            filename="gz-sim-pose-publisher-system"
            name="gz::sim::systems::PosePublisher">
            <publish_link_pose>true</publish_link_pose>
            <use_pose_vector_msg>true</use_pose_vector_msg>
            <static_publisher>true</static_publisher>
            <static_update_frequency>1</static_update_frequency>
        </plugin-->
    <!--plugin
            filename="gz-sim-odometry-publisher-system"
            name="gz::sim::systems::OdometryPublisher">
            <odom_frame>robot/odom</odom_frame>
            <robot_base_frame>robot/base_link</robot_base_frame>
            <odom_publish_frequency>50</odom_publish_frequency>
        </plugin-->
    <plugin filename="gz-sim-joint-state-publisher-system" name="gz::sim::systems::JointStatePublisher">
        </plugin>
    <plugin filename="libgz-sim7-ackermann-steering-system.so" name="gz::sim::v7::systems::AckermannSteering">
      <ros>
        <namespace>demo</namespace>
        <remapping>cmd_vel:=cmd_demo</remapping>
        <remapping>odom:=odom_demo</remapping>
        <remapping>distance:=distance_demo</remapping>
      </ros>
      <update_rate>100.0</update_rate>
      <!-- wheels -->
      <front_left_joint>front_left_hub_with_wheel_joint</front_left_joint>
      <front_right_joint>front_right_hub_with_wheel_joint</front_right_joint>
      <rear_left_joint>rear_left_hub_with_wheel_joint</rear_left_joint>
      <rear_right_joint>rear_right_hub_with_wheel_joint</rear_right_joint>
      <left_steering_joint>front_left_steering_joint</left_steering_joint>
      <right_steering_joint>front_right_steering_joint</right_steering_joint>
      <!-- <steering_wheel_joint>steering_joint</steering_wheel_joint> -->
      <!-- Max absolute steer angle for tyre in radians-->
      <!-- Any cmd_vel angular z greater than this would be capped -->
      <max_steer>0.6458</max_steer>
      <!-- Max absolute steering angle of steering wheel -->
      <max_steering_angle>7.85</max_steering_angle>
      <!-- Max absolute linear speed in m/s -->
      <max_speed>20</max_speed>
      <!-- PID tuning -->
      <left_steering_pid_gain>1500 0 1</left_steering_pid_gain>
      <left_steering_i_range>0 0</left_steering_i_range>
      <right_steering_pid_gain>1500 0 1</right_steering_pid_gain>
      <right_steering_i_range>0 0</right_steering_i_range>
      <linear_velocity_pid_gain>1000 0 1</linear_velocity_pid_gain>
      <linear_velocity_i_range>0 0</linear_velocity_i_range>
      <!-- output -->
      <publish_odom>true</publish_odom>
      <publish_odom_tf>true</publish_odom_tf>
      <publish_wheel_tf>true</publish_wheel_tf>
      <publish_distance>true</publish_distance>
      <odometry_frame>odom_demo</odometry_frame>
      <robot_base_frame>chassis</robot_base_frame>
    </plugin>
  </gazebo>
  <!-- Define wheel radius, suspension parameters, and car dimensions -->
  <material name="white">
    <color rgba="1 1 1 1"/>
  </material>
  <material name="orange">
    <color rgba="1 0.3 0.1 1"/>
  </material>
  <material name="blue">
    <color rgba="0.2 0.2 1 1"/>
  </material>
  <material name="black">
    <color rgba="0 0 0 1"/>
  </material>
  <material name="red">
    <color rgba="1 0 0 1"/>
  </material>
  <link name="base_link">
  </link>
  <link name="base_footprint">
  </link>
  <joint name="base_footprint_joint" type="fixed">
    <parent link="base_link"/>
    <child link="base_footprint"/>
    <origin rpy="0 0 0" xyz="0 0 -0.138"/>
  </joint>
  <joint name="chassis_joint" type="fixed">
    <parent link="base_link"/>
    <child link="chassis_link"/>
    <origin xyz="-0.226 0 0.2"/>
  </joint>
  <!-- Car body -->
  <link name="chassis_link">
    <visual>
      <geometry>
        <box size="1.6 0.8 0.5"/>
      </geometry>
    </visual>
    <collision>
      <geometry>
        <box size="1.6 0.8 0.5"/>
      </geometry>
    </collision>
  </link>
  <gazebo reference="chassis">
    <material>Gazebo/Blue</material>
  </gazebo>
  <!-- Front left wheel -->
  <joint name="front_left_steering_joint" type="revolute">
    <origin xyz="0.75 0.4 -0.0"/>
    <parent link="chassis_link"/>
    <child link="front_left_suspension_link"/>
    <axis xyz="0 0 1"/>
    <limit effort="100" velocity="1.0"/>
  </joint>
  <!-- Front right wheel -->
  <joint name="front_right_steering_joint" type="revolute">
    <origin xyz="0.75 -0.4 -0.0"/>
    <parent link="chassis_link"/>
    <child link="front_right_suspension_link"/>
    <axis xyz="0 0 1"/>
    <limit effort="100" velocity="1.0"/>
  </joint>
  <!-- Rear left wheel -->
  <joint name="rear_left_chassis_joint" type="fixed">
    <origin xyz="-0.75 0.4 -0.0"/>
    <parent link="chassis_link"/>
    <child link="rear_left_suspension_link"/>
  </joint>
  <!-- Rear ight wheel -->
  <joint name="rear_right_chassis_joint" type="fixed">
    <origin xyz="-0.75 -0.4 -0.0"/>
    <parent link="chassis_link"/>
    <child link="rear_right_suspension_link"/>
  </joint>
  <link name="front_left_wheel_link">
    <visual>
      <geometry>
        <cylinder length="0.1" radius="0.2"/>
      </geometry>
      <origin rpy="1.5707963267948966 0 0" xyz="0 0 0"/>
    </visual>
    <collision>
      <geometry>
        <cylinder length="0.1" radius="0.2"/>
      </geometry>
      <origin rpy="1.5707963267948966 0 0" xyz="0 0 0"/>
    </collision>
    <inertial>
      <origin rpy="1.5707963267948966 0 0" xyz="0 0 0"/>
      <mass value="1.0"/>
      <inertia ixx="0.1" ixy="0.0" ixz="0.0" iyy="0.1" iyz="0.0" izz="0.1"/>
    </inertial>
  </link>
  <gazebo reference="front_left_wheel">
    <material>Gazebo/Blue</material>
  </gazebo>
  <link name="front_right_wheel_link">
    <visual>
      <geometry>
        <cylinder length="0.1" radius="0.2"/>
      </geometry>
      <origin rpy="1.5707963267948966 0 0" xyz="0 0 0"/>
    </visual>
    <collision>
      <geometry>
        <cylinder length="0.1" radius="0.2"/>
      </geometry>
      <origin rpy="1.5707963267948966 0 0" xyz="0 0 0"/>
    </collision>
    <inertial>
      <origin rpy="1.5707963267948966 0 0" xyz="0 0 0"/>
      <mass value="1.0"/>
      <inertia ixx="0.1" ixy="0.0" ixz="0.0" iyy="0.1" iyz="0.0" izz="0.1"/>
    </inertial>
  </link>
  <gazebo reference="front_right_wheel">
    <material>Gazebo/Blue</material>
  </gazebo>
  <link name="rear_left_wheel_link">
    <visual>
      <geometry>
        <cylinder length="0.1" radius="0.2"/>
      </geometry>
      <origin rpy="1.5707963267948966 0 0" xyz="0 0 0"/>
    </visual>
    <collision>
      <geometry>
        <cylinder length="0.1" radius="0.2"/>
      </geometry>
      <origin rpy="1.5707963267948966 0 0" xyz="0 0 0"/>
    </collision>
    <inertial>
      <origin rpy="1.5707963267948966 0 0" xyz="0 0 0"/>
      <mass value="1.0"/>
      <inertia ixx="0.1" ixy="0.0" ixz="0.0" iyy="0.1" iyz="0.0" izz="0.1"/>
    </inertial>
  </link>
  <gazebo reference="rear_left_wheel">
    <material>Gazebo/Blue</material>
  </gazebo>
  <link name="rear_right_wheel_link">
    <visual>
      <geometry>
        <cylinder length="0.1" radius="0.2"/>
      </geometry>
      <origin rpy="1.5707963267948966 0 0" xyz="0 0 0"/>
    </visual>
    <collision>
      <geometry>
        <cylinder length="0.1" radius="0.2"/>
      </geometry>
      <origin rpy="1.5707963267948966 0 0" xyz="0 0 0"/>
    </collision>
    <inertial>
      <origin rpy="1.5707963267948966 0 0" xyz="0 0 0"/>
      <mass value="1.0"/>
      <inertia ixx="0.1" ixy="0.0" ixz="0.0" iyy="0.1" iyz="0.0" izz="0.1"/>
    </inertial>
  </link>
  <gazebo reference="rear_right_wheel">
    <material>Gazebo/Blue</material>
  </gazebo>
  <link name="front_left_suspension_link">
    <visual>
      <geometry>
        <cylinder length="0.2" radius="0.1"/>
      </geometry>
    </visual>
    <collision>
      <geometry>
        <cylinder length="0.2" radius="0.1"/>
      </geometry>
    </collision>
    <inertial>
      <origin xyz="0 0 0"/>
      <mass value="0.5"/>
      <inertia ixx="0.01" ixy="0.0" ixz="0.0" iyy="0.01" iyz="0.0" izz="0.01"/>
    </inertial>
  </link>
  <gazebo reference="front_left_suspension">
    <material>Gazebo/Blue</material>
  </gazebo>
  <link name="front_right_suspension_link">
    <visual>
      <geometry>
        <cylinder length="0.2" radius="0.1"/>
      </geometry>
    </visual>
    <collision>
      <geometry>
        <cylinder length="0.2" radius="0.1"/>
      </geometry>
    </collision>
    <inertial>
      <origin xyz="0 0 0"/>
      <mass value="0.5"/>
      <inertia ixx="0.01" ixy="0.0" ixz="0.0" iyy="0.01" iyz="0.0" izz="0.01"/>
    </inertial>
  </link>
  <gazebo reference="front_right_suspension">
    <material>Gazebo/Blue</material>
  </gazebo>
  <link name="rear_left_suspension_link">
    <visual>
      <geometry>
        <cylinder length="0.2" radius="0.1"/>
      </geometry>
    </visual>
    <collision>
      <geometry>
        <cylinder length="0.2" radius="0.1"/>
      </geometry>
    </collision>
    <inertial>
      <origin xyz="0 0 0"/>
      <mass value="0.5"/>
      <inertia ixx="0.01" ixy="0.0" ixz="0.0" iyy="0.01" iyz="0.0" izz="0.01"/>
    </inertial>
  </link>
  <gazebo reference="rear_left_suspension">
    <material>Gazebo/Blue</material>
  </gazebo>
  <link name="rear_right_suspension_link">
    <visual>
      <geometry>
        <cylinder length="0.2" radius="0.1"/>
      </geometry>
    </visual>
    <collision>
      <geometry>
        <cylinder length="0.2" radius="0.1"/>
      </geometry>
    </collision>
    <inertial>
      <origin xyz="0 0 0"/>
      <mass value="0.5"/>
      <inertia ixx="0.01" ixy="0.0" ixz="0.0" iyy="0.01" iyz="0.0" izz="0.01"/>
    </inertial>
  </link>
  <gazebo reference="rear_right_suspension">
    <material>Gazebo/Blue</material>
  </gazebo>
  <link name="front_left_hub_link">
    <visual>
      <geometry>
        <sphere radius="0.01"/>
      </geometry>
    </visual>
    <collision>
      <geometry>
        <sphere radius="0.01"/>
      </geometry>
    </collision>
    <inertial>
      <origin xyz="0 0 0"/>
      <mass value="1.0"/>
      <inertia ixx="0.01" ixy="0.0" ixz="0.0" iyy="0.01" iyz="0.0" izz="0.01"/>
    </inertial>
  </link>
  <gazebo reference="front_left_hub">
    <material>Gazebo/Blue</material>
  </gazebo>
  <link name="front_right_hub_link">
    <visual>
      <geometry>
        <sphere radius="0.01"/>
      </geometry>
    </visual>
    <collision>
      <geometry>
        <sphere radius="0.01"/>
      </geometry>
    </collision>
    <inertial>
      <origin xyz="0 0 0"/>
      <mass value="1.0"/>
      <inertia ixx="0.01" ixy="0.0" ixz="0.0" iyy="0.01" iyz="0.0" izz="0.01"/>
    </inertial>
  </link>
  <gazebo reference="front_right_hub">
    <material>Gazebo/Blue</material>
  </gazebo>
  <link name="rear_left_hub_link">
    <visual>
      <geometry>
        <sphere radius="0.01"/>
      </geometry>
    </visual>
    <collision>
      <geometry>
        <sphere radius="0.01"/>
      </geometry>
    </collision>
    <inertial>
      <origin xyz="0 0 0"/>
      <mass value="1.0"/>
      <inertia ixx="0.01" ixy="0.0" ixz="0.0" iyy="0.01" iyz="0.0" izz="0.01"/>
    </inertial>
  </link>
  <gazebo reference="rear_left_hub">
    <material>Gazebo/Blue</material>
  </gazebo>
  <link name="rear_right_hub_link">
    <visual>
      <geometry>
        <sphere radius="0.01"/>
      </geometry>
    </visual>
    <collision>
      <geometry>
        <sphere radius="0.01"/>
      </geometry>
    </collision>
    <inertial>
      <origin xyz="0 0 0"/>
      <mass value="1.0"/>
      <inertia ixx="0.01" ixy="0.0" ixz="0.0" iyy="0.01" iyz="0.0" izz="0.01"/>
    </inertial>
  </link>
  <gazebo reference="rear_right_hub">
    <material>Gazebo/Blue</material>
  </gazebo>
  <joint name="front_left_suspension_with_hub_joint" type="prismatic">
    <origin xyz="0 0.2 0"/>
    <parent link="front_left_suspension_link"/>
    <child link="front_left_hub_link"/>
    <axis xyz="0 0 1"/>
    <limit effort="100" lower="-0.2" upper="0.0" velocity="1.0"/>
    <dynamics damping="0.7"/>
  </joint>
  <joint name="front_right_suspension_with_hub_joint" type="prismatic">
    <origin xyz="0 -0.2 0"/>
    <parent link="front_right_suspension_link"/>
    <child link="front_right_hub_link"/>
    <axis xyz="0 0 1"/>
    <limit effort="100" lower="-0.2" upper="0.0" velocity="1.0"/>
    <dynamics damping="0.7"/>
  </joint>
  <joint name="rear_left_suspension_with_hub_joint" type="prismatic">
    <origin xyz="0 0.2 0"/>
    <parent link="rear_left_suspension_link"/>
    <child link="rear_left_hub_link"/>
    <axis xyz="0 0 1"/>
    <limit effort="100" lower="-0.2" upper="0.0" velocity="1.0"/>
    <dynamics damping="0.7"/>
  </joint>
  <joint name="rear_right_suspension_with_hub_joint" type="prismatic">
    <origin xyz="0 -0.2 0"/>
    <parent link="rear_right_suspension_link"/>
    <child link="rear_right_hub_link"/>
    <axis xyz="0 0 1"/>
    <limit effort="100" lower="-0.2" upper="0.0" velocity="1.0"/>
    <dynamics damping="0.7"/>
  </joint>
  <joint name="front_left_hub_with_wheel_joint" type="continuous">
    <origin xyz="0 0 0"/>
    <parent link="front_left_hub_link"/>
    <child link="front_left_wheel_link"/>
    <axis xyz="0 1 0"/>
  </joint>
  <joint name="front_right_hub_with_wheel_joint" type="continuous">
    <origin xyz="0 0 0"/>
    <parent link="front_right_hub_link"/>
    <child link="front_right_wheel_link"/>
    <axis xyz="0 1 0"/>
  </joint>
  <joint name="rear_left_hub_with_wheel_joint" type="continuous">
    <origin xyz="0 0 0"/>
    <parent link="rear_left_hub_link"/>
    <child link="rear_left_wheel_link"/>
    <axis xyz="0 1 0"/>
  </joint>
  <joint name="rear_right_hub_with_wheel_joint" type="continuous">
    <origin xyz="0 0 0"/>
    <parent link="rear_right_hub_link"/>
    <child link="rear_right_wheel_link"/>
    <axis xyz="0 1 0"/>
  </joint>
</robot>
